<?xml version="1.0"?>
<robot name="panda_US">
  <!-- Base link -->
  <link name="base_link">
    <visual>
      <geometry>
        <box size="0.1 0.1 0.1"/>
      </geometry>
    </visual>
    <inertial>
      <mass value="1.0"/>
      <inertia ixx="0.01" ixy="0" ixz="0" iyy="0.01" iyz="0" izz="0.01"/>
    </inertial>
  </link>

  <!-- Link 1 -->
  <link name="link1">
    <visual>
      <geometry>
        <cylinder radius="0.05" length="0.3"/>
      </geometry>
    </visual>
    <inertial>
      <mass value="2.0"/>
      <inertia ixx="0.02" ixy="0" ixz="0" iyy="0.02" iyz="0" izz="0.005"/>
    </inertial>
  </link>

  <!-- Link 2 -->
  <link name="link2">
    <visual>
      <geometry>
        <cylinder radius="0.05" length="0.3"/>
      </geometry>
    </visual>
    <inertial>
      <mass value="2.0"/>
      <inertia ixx="0.02" ixy="0" ixz="0" iyy="0.02" iyz="0" izz="0.005"/>
    </inertial>
  </link>

  <!-- Link 3 -->
  <link name="link3">
    <visual>
      <geometry>
        <cylinder radius="0.05" length="0.3"/>
      </geometry>
    </visual>
    <inertial>
      <mass value="2.0"/>
      <inertia ixx="0.02" ixy="0" ixz="0" iyy="0.02" iyz="0" izz="0.005"/>
    </inertial>
  </link>

  <!-- Link 4 -->
  <link name="link4">
    <visual>
      <geometry>
        <cylinder radius="0.05" length="0.25"/>
      </geometry>
    </visual>
    <inertial>
      <mass value="1.5"/>
      <inertia ixx="0.015" ixy="0" ixz="0" iyy="0.015" iyz="0" izz="0.004"/>
    </inertial>
  </link>

  <!-- Link 5 -->
  <link name="link5">
    <visual>
      <geometry>
        <cylinder radius="0.05" length="0.25"/>
      </geometry>
    </visual>
    <inertial>
      <mass value="1.5"/>
      <inertia ixx="0.015" ixy="0" ixz="0" iyy="0.015" iyz="0" izz="0.004"/>
    </inertial>
  </link>

  <!-- Link 6 -->
  <link name="link6">
    <visual>
      <geometry>
        <cylinder radius="0.04" length="0.2"/>
      </geometry>
    </visual>
    <inertial>
      <mass value="1.0"/>
      <inertia ixx="0.01" ixy="0" ixz="0" iyy="0.01" iyz="0" izz="0.003"/>
    </inertial>
  </link>

  <!-- Link 7 (end-effector) -->
  <link name="link7">
    <visual>
      <geometry>
        <cylinder radius="0.03" length="0.1"/>
      </geometry>
    </visual>
    <inertial>
      <mass value="0.5"/>
      <inertia ixx="0.005" ixy="0" ixz="0" iyy="0.005" iyz="0" izz="0.002"/>
    </inertial>
  </link>

  <!-- Joint 1 -->
  <joint name="joint1" type="revolute">
    <parent link="base_link"/>
    <child link="link1"/>
    <origin xyz="0 0 0.15" rpy="0 0 0"/>
    <axis xyz="0 0 1"/>
    <limit lower="-2.8973" upper="2.8973" effort="87" velocity="2.1750"/>
  </joint>

  <!-- Joint 2 -->
  <joint name="joint2" type="revolute">
    <parent link="link1"/>
    <child link="link2"/>
    <origin xyz="0 0 0.15" rpy="-1.5708 0 0"/>
    <axis xyz="0 0 1"/>
    <limit lower="-1.7628" upper="1.7628" effort="87" velocity="2.1750"/>
  </joint>

  <!-- Joint 3 -->
  <joint name="joint3" type="revolute">
    <parent link="link2"/>
    <child link="link3"/>
    <origin xyz="0 0 0.15" rpy="1.5708 0 0"/>
    <axis xyz="0 0 1"/>
    <limit lower="-2.8973" upper="2.8973" effort="87" velocity="2.1750"/>
  </joint>

  <!-- Joint 4 -->
  <joint name="joint4" type="revolute">
    <parent link="link3"/>
    <child link="link4"/>
    <origin xyz="0.0825 0 0" rpy="1.5708 0 0"/>
    <axis xyz="0 0 1"/>
    <limit lower="-3.0718" upper="-0.0698" effort="87" velocity="2.1750"/>
  </joint>

  <!-- Joint 5 -->
  <joint name="joint5" type="revolute">
    <parent link="link4"/>
    <child link="link5"/>
    <origin xyz="-0.0825 0 0.125" rpy="-1.5708 0 0"/>
    <axis xyz="0 0 1"/>
    <limit lower="-2.8973" upper="2.8973" effort="12" velocity="2.6100"/>
  </joint>

  <!-- Joint 6 -->
  <joint name="joint6" type="revolute">
    <parent link="link5"/>
    <child link="link6"/>
    <origin xyz="0 0 0.125" rpy="1.5708 0 0"/>
    <axis xyz="0 0 1"/>
    <limit lower="-0.0175" upper="3.7525" effort="12" velocity="2.6100"/>
  </joint>

  <!-- Joint 7 -->
  <joint name="joint7" type="revolute">
    <parent link="link6"/>
    <child link="link7"/>
    <origin xyz="0.088 0 0" rpy="1.5708 0 0"/>
    <axis xyz="0 0 1"/>
    <limit lower="-2.8973" upper="2.8973" effort="12" velocity="2.6100"/>
  </joint>

</robot>
